<mujoco model="panda_sort_scene">
  <!--
    OSC (primary):
      - Uses torque actuators (actuator group "osc_torque")
      - Controller computes: tau = J^T * (Kp * pos_err - Kd * vel) + gravity_comp
      - Gripper controlled via separate position actuators
  
    
    To switch between them, the env selects which actuators to use.
    Both sets of actuators are in the XML — env activates one set.
  -->

  <compiler meshdir="franka_emika_panda/assets" angle="radian" autolimits="true"/>

  <option timestep="0.002" iterations="50" ls_iterations="50"
          integrator="implicitfast" cone="elliptic">
    <flag eulerdamp="disable"/>
  </option>

  <visual>
    <headlight diffuse="0.6 0.6 0.6" ambient="0.3 0.3 0.3" specular="0 0 0"/>
    <global azimuth="120" elevation="-20"/>
  </visual>

  <default>
    <default class="panda">
      <material specular="0.5" shininess="0.25"/>
      <joint armature="0.1" damping="1" axis="0 0 1" range="-2.8973 2.8973"/>
      <general dyntype="none" biastype="affine" ctrlrange="-2.8973 2.8973" forcerange="-87 87"/>
      <default class="finger">
        <joint axis="0 1 0" type="slide" range="0 0.04"/>
      </default>
      <default class="visual">
        <geom type="mesh" contype="0" conaffinity="0" group="2"/>
      </default>
      <default class="collision">
        <geom group="3" type="mesh" condim="3"/>
        <default class="fingertip_pad_collision_1">
          <geom type="box" size="0.0085 0.004 0.0085" pos="0 0.0055 0.0445"
                condim="3" friction="0.8 0.8 0.8"/>
        </default>
        <default class="fingertip_pad_collision_2">
          <geom type="box" size="0.003 0.002 0.003" pos="0.0055 0.002 0.05"
                condim="3" friction="0.8 0.8 0.8"/>
        </default>
        <default class="fingertip_pad_collision_3">
          <geom type="box" size="0.003 0.002 0.003" pos="-0.0055 0.002 0.05"
                condim="3" friction="0.8 0.8 0.8"/>
        </default>
        <default class="fingertip_pad_collision_4">
          <geom type="box" size="0.003 0.002 0.0035" pos="0.0055 0.002 0.0395"
                condim="3" friction="0.8 0.8 0.8"/>
        </default>
        <default class="fingertip_pad_collision_5">
          <geom type="box" size="0.003 0.002 0.0035" pos="-0.0055 0.002 0.0395"
                condim="3" friction="0.8 0.8 0.8"/>
        </default>
      </default>
    </default>
  </default>

  <asset>
    <!-- Panda materials -->
    <material class="panda" name="white" rgba="1 1 1 1"/>
    <material class="panda" name="off_white" rgba="0.901961 0.921569 0.929412 1"/>
    <material class="panda" name="black" rgba="0.25 0.25 0.25 1"/>
    <material class="panda" name="green" rgba="0 1 0 1"/>
    <material class="panda" name="light_blue" rgba="0.039216 0.541176 0.780392 1"/>

    <!-- Collision meshes -->
    <mesh name="link0_c" file="link0.stl"/>
    <mesh name="link1_c" file="link1.stl"/>
    <mesh name="link2_c" file="link2.stl"/>
    <mesh name="link3_c" file="link3.stl"/>
    <mesh name="link4_c" file="link4.stl"/>
    <mesh name="link5_c0" file="link5_collision_0.obj"/>
    <mesh name="link5_c1" file="link5_collision_1.obj"/>
    <mesh name="link5_c2" file="link5_collision_2.obj"/>
    <mesh name="link6_c" file="link6.stl"/>
    <mesh name="link7_c" file="link7.stl"/>
    <mesh name="hand_c" file="hand.stl"/>

    <!-- Visual meshes -->
    <mesh file="link0_0.obj"/><mesh file="link0_1.obj"/><mesh file="link0_2.obj"/>
    <mesh file="link0_3.obj"/><mesh file="link0_4.obj"/><mesh file="link0_5.obj"/>
    <mesh file="link0_7.obj"/><mesh file="link0_8.obj"/><mesh file="link0_9.obj"/>
    <mesh file="link0_10.obj"/><mesh file="link0_11.obj"/>
    <mesh file="link1.obj"/><mesh file="link2.obj"/>
    <mesh file="link3_0.obj"/><mesh file="link3_1.obj"/><mesh file="link3_2.obj"/><mesh file="link3_3.obj"/>
    <mesh file="link4_0.obj"/><mesh file="link4_1.obj"/><mesh file="link4_2.obj"/><mesh file="link4_3.obj"/>
    <mesh file="link5_0.obj"/><mesh file="link5_1.obj"/><mesh file="link5_2.obj"/>
    <mesh file="link6_0.obj"/><mesh file="link6_1.obj"/><mesh file="link6_2.obj"/><mesh file="link6_3.obj"/>
    <mesh file="link6_4.obj"/><mesh file="link6_5.obj"/><mesh file="link6_6.obj"/><mesh file="link6_7.obj"/>
    <mesh file="link6_8.obj"/><mesh file="link6_9.obj"/><mesh file="link6_10.obj"/><mesh file="link6_11.obj"/>
    <mesh file="link6_12.obj"/><mesh file="link6_13.obj"/><mesh file="link6_14.obj"/>
    <mesh file="link6_15.obj"/><mesh file="link6_16.obj"/>
    <mesh file="link7_0.obj"/><mesh file="link7_1.obj"/><mesh file="link7_2.obj"/><mesh file="link7_3.obj"/>
    <mesh file="link7_4.obj"/><mesh file="link7_5.obj"/><mesh file="link7_6.obj"/><mesh file="link7_7.obj"/>
    <mesh file="hand_0.obj"/><mesh file="hand_1.obj"/><mesh file="hand_2.obj"/>
    <mesh file="hand_3.obj"/><mesh file="hand_4.obj"/>
    <mesh file="finger_0.obj"/><mesh file="finger_1.obj"/>

    <!-- Scene materials -->
    <texture type="2d" name="floor_tex" builtin="checker"
             rgb1="0.3 0.3 0.3" rgb2="0.2 0.2 0.2" width="512" height="512"/>
    <material name="floor_mat" texture="floor_tex" texrepeat="4 4" reflectance="0.1"/>
    <texture type="2d" name="table_tex" builtin="flat"
             rgb1="0.65 0.60 0.50" width="512" height="512"/>
    <material name="table_mat" texture="table_tex" specular="0.1" shininess="0.1"/>
    <material name="bin_red"  rgba="0.85 0.15 0.15 0.6"/>
    <material name="bin_blue" rgba="0.15 0.15 0.85 0.6"/>
  </asset>

  <worldbody>
    <!-- Lighting -->
    <light name="top" pos="0 0 2" mode="trackcom"/>
    <light name="main_light" pos="0 0 2.5" dir="0 0 -1"
           diffuse="0.8 0.8 0.8" specular="0.2 0.2 0.2" castshadow="true"/>
    <light name="fill_light" pos="1.0 1.0 2.0" dir="-0.5 -0.5 -1"
           diffuse="0.3 0.3 0.3" specular="0 0 0"/>

    <!-- Floor -->
    <geom name="floor" type="plane" size="2 2 0.05"
          material="floor_mat" contype="1" conaffinity="1"/>


    <!-- PANDA ROBOT -->
    <body name="link0" childclass="panda">
      <inertial mass="0.629769" pos="-0.041018 -0.00014 0.049974"
        fullinertia="0.00315 0.00388 0.004285 8.2904e-7 0.00015 8.2299e-6"/>
      <geom mesh="link0_0" material="off_white" class="visual"/>
      <geom mesh="link0_1" material="black" class="visual"/>
      <geom mesh="link0_2" material="off_white" class="visual"/>
      <geom mesh="link0_3" material="black" class="visual"/>
      <geom mesh="link0_4" material="off_white" class="visual"/>
      <geom mesh="link0_5" material="black" class="visual"/>
      <geom mesh="link0_7" material="white" class="visual"/>
      <geom mesh="link0_8" material="white" class="visual"/>
      <geom mesh="link0_9" material="black" class="visual"/>
      <geom mesh="link0_10" material="off_white" class="visual"/>
      <geom mesh="link0_11" material="white" class="visual"/>
      <geom mesh="link0_c" class="collision"/>
      <body name="link1" pos="0 0 0.333">
        <inertial mass="4.970684" pos="0.003875 0.002081 -0.04762"
          fullinertia="0.70337 0.70661 0.0091170 -0.00013900 0.0067720 0.019169"/>
        <joint name="joint1" damping="40"/>
        <geom material="white" mesh="link1" class="visual"/>
        <geom mesh="link1_c" class="collision"/>
        <body name="link2" quat="1 -1 0 0">
          <inertial mass="0.646926" pos="-0.003141 -0.02872 0.003495"
            fullinertia="0.0079620 2.8110e-2 2.5995e-2 -3.925e-3 1.0254e-2 7.04e-4"/>
          <joint name="joint2" range="-1.7628 1.7628" damping="40"/>
          <geom material="white" mesh="link2" class="visual"/>
          <geom mesh="link2_c" class="collision"/>
          <body name="link3" pos="0 -0.316 0" quat="1 1 0 0">
            <joint name="joint3" damping="40"/>
            <inertial mass="3.228604" pos="2.7518e-2 3.9252e-2 -6.6502e-2"
              fullinertia="3.7242e-2 3.6155e-2 1.083e-2 -4.761e-3 -1.1396e-2 -1.2805e-2"/>
            <geom mesh="link3_0" material="white" class="visual"/>
            <geom mesh="link3_1" material="white" class="visual"/>
            <geom mesh="link3_2" material="white" class="visual"/>
            <geom mesh="link3_3" material="black" class="visual"/>
            <geom mesh="link3_c" class="collision"/>
            <body name="link4" pos="0.0825 0 0" quat="1 1 0 0">
              <inertial mass="3.587895" pos="-5.317e-2 1.04419e-1 2.7454e-2"
                fullinertia="2.5853e-2 1.9552e-2 2.8323e-2 7.796e-3 -1.332e-3 8.641e-3"/>
              <joint name="joint4" range="-3.0718 -0.0698" damping="40"/>
              <geom mesh="link4_0" material="white" class="visual"/>
              <geom mesh="link4_1" material="white" class="visual"/>
              <geom mesh="link4_2" material="black" class="visual"/>
              <geom mesh="link4_3" material="white" class="visual"/>
              <geom mesh="link4_c" class="collision"/>
              <body name="link5" pos="-0.0825 0.384 0" quat="1 -1 0 0">
                <inertial mass="1.225946" pos="-1.1953e-2 4.1065e-2 -3.8437e-2"
                  fullinertia="3.5549e-2 2.9474e-2 8.627e-3 -2.117e-3 -4.037e-3 2.29e-4"/>
                <joint name="joint5" damping="2"/>
                <geom mesh="link5_0" material="black" class="visual"/>
                <geom mesh="link5_1" material="white" class="visual"/>
                <geom mesh="link5_2" material="white" class="visual"/>
                <geom mesh="link5_c0" class="collision"/>
                <geom mesh="link5_c1" class="collision"/>
                <geom mesh="link5_c2" class="collision"/>
                <body name="link6" quat="1 1 0 0">
                  <inertial mass="1.666555" pos="6.0149e-2 -1.4117e-2 -1.0517e-2"
                    fullinertia="1.964e-3 4.354e-3 5.433e-3 1.09e-4 -1.158e-3 3.41e-4"/>
                  <joint name="joint6" range="-0.0175 3.7525" damping="2"/>
                  <geom mesh="link6_0" material="off_white" class="visual"/>
                  <geom mesh="link6_1" material="white" class="visual"/>
                  <geom mesh="link6_2" material="black" class="visual"/>
                  <geom mesh="link6_3" material="white" class="visual"/>
                  <geom mesh="link6_4" material="white" class="visual"/>
                  <geom mesh="link6_5" material="white" class="visual"/>
                  <geom mesh="link6_6" material="white" class="visual"/>
                  <geom mesh="link6_7" material="light_blue" class="visual"/>
                  <geom mesh="link6_8" material="light_blue" class="visual"/>
                  <geom mesh="link6_9" material="black" class="visual"/>
                  <geom mesh="link6_10" material="black" class="visual"/>
                  <geom mesh="link6_11" material="white" class="visual"/>
                  <geom mesh="link6_12" material="green" class="visual"/>
                  <geom mesh="link6_13" material="white" class="visual"/>
                  <geom mesh="link6_14" material="black" class="visual"/>
                  <geom mesh="link6_15" material="black" class="visual"/>
                  <geom mesh="link6_16" material="white" class="visual"/>
                  <geom mesh="link6_c" class="collision"/>
                  <body name="link7" pos="0.088 0 0" quat="1 1 0 0">
                    <inertial mass="7.35522e-01" pos="1.0517e-2 -4.252e-3 6.1597e-2"
                      fullinertia="1.2516e-2 1.0027e-2 4.815e-3 -4.28e-4 -1.196e-3 -7.41e-4"/>
                    <joint name="joint7" damping="2"/>
                    <geom mesh="link7_0" material="white" class="visual"/>
                    <geom mesh="link7_1" material="black" class="visual"/>
                    <geom mesh="link7_2" material="black" class="visual"/>
                    <geom mesh="link7_3" material="black" class="visual"/>
                    <geom mesh="link7_4" material="black" class="visual"/>
                    <geom mesh="link7_5" material="black" class="visual"/>
                    <geom mesh="link7_6" material="black" class="visual"/>
                    <geom mesh="link7_7" material="white" class="visual"/>
                    <geom mesh="link7_c" class="collision"/>
                    <body name="hand" pos="0 0 0.107" quat="0.9238795 0 0 -0.3826834">
                      <inertial mass="0.73" pos="-0.01 0 0.03" diaginertia="0.001 0.0025 0.0017"/>
                      <geom mesh="hand_0" material="off_white" class="visual"/>
                      <geom mesh="hand_1" material="black" class="visual"/>
                      <geom mesh="hand_2" material="black" class="visual"/>
                      <geom mesh="hand_3" material="white" class="visual"/>
                      <geom mesh="hand_4" material="off_white" class="visual"/>
                      <geom mesh="hand_c" class="collision"/>

                      <!-- EE center — between the fingers, same as panda_mujoco_gym -->
                      <body name="ee_center_body" pos="0 0 0.105">
                        <site name="ee_center_site" size="0.01" group="3"/>
                      </body>

                      <!-- Old gripper site kept for backward compatibility -->
                      <site name="gripper" pos="0 0 0.1034"/>

                      <body name="left_finger" pos="0 0 0.0584">
                        <inertial mass="0.015" pos="0 0 0" diaginertia="2.375e-6 2.375e-6 7.5e-7"/>
                        <joint name="finger_joint1" class="finger" damping="10"/>
                        <geom mesh="finger_0" material="off_white" class="visual"/>
                        <geom mesh="finger_1" material="black" class="visual"/>
                        <geom mesh="finger_0" class="collision"/>
                        <geom class="fingertip_pad_collision_1"/>
                        <geom class="fingertip_pad_collision_2"/>
                        <geom class="fingertip_pad_collision_3"/>
                        <geom class="fingertip_pad_collision_4"/>
                        <geom class="fingertip_pad_collision_5"/>
                      </body>
                      <body name="right_finger" pos="0 0 0.0584" quat="0 0 0 1">
                        <inertial mass="0.015" pos="0 0 0" diaginertia="2.375e-6 2.375e-6 7.5e-7"/>
                        <joint name="finger_joint2" class="finger" damping="10"/>
                        <geom mesh="finger_0" material="off_white" class="visual"/>
                        <geom mesh="finger_1" material="black" class="visual"/>
                        <geom mesh="finger_0" class="collision"/>
                        <geom class="fingertip_pad_collision_1"/>
                        <geom class="fingertip_pad_collision_2"/>
                        <geom class="fingertip_pad_collision_3"/>
                        <geom class="fingertip_pad_collision_4"/>
                        <geom class="fingertip_pad_collision_5"/>
                      </body>
                    </body>
                  </body>
                </body>
              </body>
            </body>
          </body>
        </body>
      </body>
    </body>

    
    <!-- TABLE -->
    <body name="table" pos="0.5 0.0 0.0">
      <geom name="table_top" type="box" size="0.40 0.30 0.015"
            pos="0 0 0.405" material="table_mat"
            contype="1" conaffinity="1" friction="0.8 0.01 0.001"/>
      <geom name="leg_fl" type="box" size="0.02 0.02 0.195"
            pos="-0.37 -0.27 0.21" rgba="0.4 0.35 0.3 1"/>
      <geom name="leg_fr" type="box" size="0.02 0.02 0.195"
            pos="-0.37  0.27 0.21" rgba="0.4 0.35 0.3 1"/>
      <geom name="leg_bl" type="box" size="0.02 0.02 0.195"
            pos=" 0.37 -0.27 0.21" rgba="0.4 0.35 0.3 1"/>
      <geom name="leg_br" type="box" size="0.02 0.02 0.195"
            pos=" 0.37  0.27 0.21" rgba="0.4 0.35 0.3 1"/>
    </body>

    
    <!-- BINS -->
    
    <body name="bin_red" pos="0.72 -0.18 0.421">
      <geom name="bin_red_marker" type="box" size="0.08 0.08 0.001"
            material="bin_red" contype="0" conaffinity="0"/>
      <geom type="box" size="0.08 0.005 0.02" pos="0  0.08 0.02"
            material="bin_red" contype="1" conaffinity="1" friction="0.8 0.01 0.01"
            solimp="0.99 0.999 0.001" solref="0.01 1"/>
      <geom type="box" size="0.08 0.005 0.02" pos="0 -0.08 0.02"
            material="bin_red" contype="1" conaffinity="1" friction="0.8 0.01 0.01"
            solimp="0.99 0.999 0.001" solref="0.01 1"/>
      <geom type="box" size="0.005 0.08 0.02" pos=" 0.08 0 0.02"
            material="bin_red" contype="1" conaffinity="1" friction="0.8 0.01 0.01"
            solimp="0.99 0.999 0.001" solref="0.01 1"/>
      <geom type="box" size="0.005 0.08 0.02" pos="-0.08 0 0.02"
            material="bin_red" contype="1" conaffinity="1" friction="0.8 0.01 0.01"
            solimp="0.99 0.999 0.001" solref="0.01 1"/>
    </body>

    <body name="bin_blue" pos="0.72 0.18 0.421">
      <geom name="bin_blue_marker" type="box" size="0.08 0.08 0.001"
            material="bin_blue" contype="0" conaffinity="0"/>
      <geom type="box" size="0.08 0.005 0.02" pos="0  0.08 0.02"
            material="bin_blue" contype="1" conaffinity="1" friction="0.8 0.01 0.01"
            solimp="0.99 0.999 0.001" solref="0.01 1"/>
      <geom type="box" size="0.08 0.005 0.02" pos="0 -0.08 0.02"
            material="bin_blue" contype="1" conaffinity="1" friction="0.8 0.01 0.01"
            solimp="0.99 0.999 0.001" solref="0.01 1"/>
      <geom type="box" size="0.005 0.08 0.02" pos=" 0.08 0 0.02"
            material="bin_blue" contype="1" conaffinity="1" friction="0.8 0.01 0.01"
            solimp="0.99 0.999 0.001" solref="0.01 1"/>
      <geom type="box" size="0.005 0.08 0.02" pos="-0.08 0 0.02"
            material="bin_blue" contype="1" conaffinity="1" friction="0.8 0.01 0.01"
            solimp="0.99 0.999 0.001" solref="0.01 1"/>
    </body>
    
    <!-- BALLS -->
    
    <body name="ball0" pos="0.40 -0.10 0.455">
      <joint name="ball0_joint" type="free" damping="0.07"/>
      <geom name="ball0_geom" type="sphere" size="0.025"
            rgba="0.85 0.15 0.15 1" mass="0.05"
            friction="0.8 0.01 0.01" condim="6"
            solimp="0.99 0.999 0.001" solref="0.005 1"
            contype="1" conaffinity="1"/>
    </body>
    <body name="ball1" pos="0.50 0.05 0.455">
      <joint name="ball1_joint" type="free" damping="0.07"/>
      <geom name="ball1_geom" type="sphere" size="0.025"
            rgba="0.15 0.15 0.85 1" mass="0.05"
            friction="0.8 0.01 0.01" condim="6"
            solimp="0.99 0.999 0.001" solref="0.005 1"
            contype="1" conaffinity="1"/>
    </body>
    <body name="ball2" pos="0.60 -0.05 0.455">
      <joint name="ball2_joint" type="free" damping="0.07"/>
      <geom name="ball2_geom" type="sphere" size="0.025"
            rgba="0.85 0.15 0.15 1" mass="0.05"
            friction="0.8 0.01 0.01" condim="6"
            solimp="0.99 0.999 0.001" solref="0.005 1"
            contype="1" conaffinity="1"/>
    </body>
    <body name="ball3" pos="0.55 0.15 0.455">
      <joint name="ball3_joint" type="free" damping="0.07"/>
      <geom name="ball3_geom" type="sphere" size="0.025"
            rgba="0.15 0.15 0.85 1" mass="0.05"
            friction="0.8 0.01 0.01" condim="6"
            solimp="0.99 0.999 0.001" solref="0.005 1"
            contype="1" conaffinity="1"/>
    </body>

    
    <!-- CAMERAS -->
    
    <camera name="overhead_cam" pos="0.5 0.0 1.2"
            euler="0 0 3.14159" fovy="55"/>
    <camera name="side_cam" pos="-0.3 -0.8 0.8"
            xyaxes="1 0 0 0 0.5 1" fovy="45"/>
  </worldbody>


  <equality>
    <joint joint1="finger_joint1" joint2="finger_joint2"
           solimp="0.95 0.99 0.001" solref="0.005 1"/>
  </equality>

  
  <!-- ACTUATORS                                                         -->
  <!--                                                                   -->
  <!-- Arm joints: general actuators with high gains (affine bias).      -->
  <!--   - For OSC: env writes torques directly to data.qfrc_applied     -->
  <!--     and these actuators hold the arm at neutral (low activity)    -->
  <!--                                                                   -->
  <!-- Gripper: separate position actuators for both approaches          -->
  
  <actuator>
    <!-- Arm — high gain general actuators (same as panda_mujoco_gym) -->
    <general class="panda" name="actuator1" joint="joint1"
             gainprm="4500" biasprm="0 -4500 -450"/>
    <general class="panda" name="actuator2" joint="joint2"
             gainprm="4500" biasprm="0 -4500 -450" ctrlrange="-1.7628 1.7628"/>
    <general class="panda" name="actuator3" joint="joint3"
             gainprm="3500" biasprm="0 -3500 -350"/>
    <general class="panda" name="actuator4" joint="joint4"
             gainprm="3500" biasprm="0 -3500 -350" ctrlrange="-3.0718 -0.0698"/>
    <general class="panda" name="actuator5" joint="joint5"
             gainprm="2000" biasprm="0 -2000 -200" forcerange="-12 12"/>
    <general class="panda" name="actuator6" joint="joint6"
             gainprm="2000" biasprm="0 -2000 -200" forcerange="-12 12"
             ctrlrange="-0.0175 3.7525"/>
    <general class="panda" name="actuator7" joint="joint7"
             gainprm="2000" biasprm="0 -2000 -200" forcerange="-12 12"/>

    <!-- Gripper — proportional position control -->
    <general name="finger_actuator1" joint="finger_joint1" class="panda"
             gainprm="500 0 0" biasprm="0 -500 -10"
             forcerange="-120 120" ctrlrange="0 0.04"/>
    <general name="finger_actuator2" joint="finger_joint2" class="panda"
             gainprm="500 0 0" biasprm="0 -500 -10"
             forcerange="-120 120" ctrlrange="0 0.04"/>
  </actuator>

  <contact>
    <exclude body1="link0" body2="link1"/>
  </contact>

</mujoco>